Workbook

Sheet Balance Sheet
B1: Balance Sheet — Exxon Mobil Corporation (XOM)
B2: ASSETS | C2: FY2024 (Dec 31, 2024) | D2: FY2023 (Dec 31, 2023) | F2: LIABILITIES & EQUITY | G2: FY2024 (Dec 31, 2024) | H2: FY2023 (Dec 31, 2023)
B3: (All figures in $millions) | F3: (All figures in $millions)
B4: Current Assets | F4: Current Liabilities
B5: Cash and cash equivalents | C5: 23029 | D5: 31539 | F5: Notes and loans payable (short-term debt) | G5: 6335 | H5: 4090
B6: Notes and accounts receivable – net | C6: 43681 | D6: 38015 | F6: Accounts payable and accrued liabilities | G6: 65352 | H6: 61226
B7: Inventories | C7: 19567 | D7: 25120 | F7: Income taxes payable | G7: 643 | H7: 3910
B8: Other current assets | C8: 4713 | D8: 1935 | F8: Total current liabilities | G8: =G5+G6+G7 -> 72330 | H8: =H5+H6+H7 -> 69226
B9: Total current assets | C9: =C5+C6+C7+C8 -> 90990 | D9: =D5+D6+D7+D8 -> 96609
F10: Long-term debt | G10: 35365 | H10: 37483
B11: Fixed Assets | F11: Other long-term liabilities | G11: 75807 | H11: 60980
B12: Property, plant, and equipment (gross) | C12: 457594 | D12: 359838
B13: Less accumulated depreciation | C13: 144040 | D13: 144898 | F13: Total Liabilities | G13: =G8+G10+G11 -> 183502 | H13: =H8+H10+H11 -> 167689
B14: Net tangible fixed assets | C14: =C12-C13 -> 313554 | D14: =D12-D13 -> 214940
F15: Shareholders' Equity
B16: Other Assets | F16: Common stock and paid-in capital | G16: 47234 | H16: 17781
B17: Investments, advances & other assets | C17: =C20-C9-C14 -> 48931 | D17: =D20-D9-D14 -> 64768 | F17: Earnings reinvested (net of treasury) | G17: 222613 | H17: 187021
F18: Noncontrolling interests | G18: 7240 | H18: 7736
F19: Total shareholders' equity | G19: =G16+G17+G18 -> 277087 | H19: =H16+H17+H18 -> 212538
B20: Total Assets | C20: 453475 | D20: 376317 | F20: Total Liabilities + Equity | G20: =G13+G19 -> 460589 | H20: =H13+H19 -> 380227
B21: Balance Check (TA − TL&E) | C21: =C20-G20 -> -7114
B22: Source: ExxonMobil 10-K FY2024, SEC EDGAR

Sheet Income Statement
B1: Income Statement — Exxon Mobil Corporation (XOM)
B2: Line Item | C2: FY2024 (Dec 31, 2024) | D2: % of Sales
B3: (All figures in $millions)
B4: Net sales / revenues | C4: 339247 | D4: =IF(C$4=0,0,C4/C$4) -> 1
B5: less Cost of goods sold (purchases, manufacturing) | C5: 239063 | D5: =IF(C$4=0,0,C5/C$4) -> 0.70468715
B6: less Selling, general & administrative | C6: 9976 | D6: =IF(C$4=0,0,C6/C$4) -> 0.029406303
B7: less Depreciation and depletion | C7: 23442 | D7: =IF(C$4=0,0,C7/C$4) -> 0.069100095
B8: Earnings before interest & taxes (EBIT) | C8: =C4-C5-C6-C7 -> 66766 | D8: =IF(C$4=0,0,C8/C$4) -> 0.19680646
D9: 0
B10: plus Other income (interest income + other non-op) | C10: 4144 | D10: =IF(C$4=0,0,C10/C$4) -> 0.012215289
B11: less Interest expense | C11: 996 | D11: =IF(C$4=0,0,C11/C$4) -> 0.002935914
B12: Taxable income | C12: =C8+C10-C11 -> 69914 | D12: =IF(C$4=0,0,C12/C$4) -> 0.20608583
B14: less Taxes | C14: 13810 | D14: =IF(C$4=0,0,C14/C$4) -> 0.040707803
B15: Net income (attributable to ExxonMobil) | C15: =C12-C14 -> 56104 | D15: =IF(C$4=0,0,C15/C$4) -> 0.16537803
B17: Allocation of Net Income | C17: =C15 -> 56104
B18: Dividends | C18: 16700 | D18: =IF(C$4=0,0,C18/C$4) -> 0.04922667
B19: Addition to retained earnings | C19: =C17-C18 -> 39404 | D19: =IF(C$4=0,0,C19/C$4) -> 0.11615136
B21: Source: ExxonMobil 10-K FY2024, SEC EDGAR

Sheet Cash Flow Statement
B1: Cash Flow Statement — Exxon Mobil Corporation (XOM)
B2: Line Item | C2: FY2024 (Dec 31, 2024) | D2: Source / Notes
B3: (All figures in $millions)
B4: Operations:
B5: Net income | C5: ='Income Statement'!C15 -> 56104 | D5: [Income Statement]
B6: plus Depreciation and depletion | C6: ='Income Statement'!C7 -> 23442 | D6: [Income Statement]
B7: plus Changes in working capital items
B8: Decrease (increase) in accounts receivable | C8: -5666 | D8: [Balance Sheet]
B9: Decrease (increase) in inventories | C9: 5553 | D9: [Balance Sheet]
B10: Decrease (increase) in other current assets | C10: -2778 | D10: [Balance Sheet]
B11: Increase (decrease) in accounts payable | C11: 4126 | D11: [Balance Sheet]
B12: Increase (decrease) in income taxes payable | C12: -3267 | D12: [Balance Sheet]
B13: Total change in working capital | C13: =C8+C9+C10+C11+C12 -> -2032
B14: Cash provided by operations | C14: =C5+C6+C13 -> 77514
B16: Investments:
B17: Capital expenditures (additions to PP&E) | C17: -24306
B18: plus Additional investments and advances | C18: -3299
B19: plus Proceeds from asset sales | C19: 4987
B20: Cash provided by (used for) investments | C20: =C17+C18+C19 -> -22618
B22: Financing activities:
B23: Increase (decrease) in short-term debt | C23: 2245
B24: plus Increase (decrease) in long-term debt | C24: -2118
B25: plus Dividends | C25: -16700
B26: plus Issues (repurchases) of stock (net) | C26: -19300
B27: plus Other financing activities | C27: -3627
B28: Cash provided by (used for) financing | C28: =C23+C24+C25+C26+C27 -> -39500
B30: Net increase (decrease) in cash | C30: =C14+C20+C28 -> 15396
B32: Source: ExxonMobil 10-K FY2024, SEC EDGAR

Sheet Ratios
B1: Ratios — Exxon Mobil Corporation (XOM)
B2: Metric | C2: Input | D2: Named Range Formula | E2: Named Range
B3: Current year | C3: 2024 | E3: yearCurrent
B4: Start of year | C4: 2023 | D4: yearCurrent - 1 | E4: yearStart
B5: Share price | C5: 103.76 | E5: share_price
B6: Shares outstanding (M) | C6: 4298 | E6: shares_outstanding
B7: Cost of capital | C7: 0.09 | E7: cost_capital
B8: Tax rate | C8: 0.2826 | E8: tax_rate
B9: Market capitalization | C9: =C5*C6 -> 445960.48 | D9: share_price × shares_outstanding | E9: market_capitalization
B11: ─── Start of Year (Prior Year Balance Sheet) ───
B12: Equity (start of year) | C12: ='Balance Sheet'!H19 -> 212538 | D12: BAL_equity_shareholders_2023 | E12: startYear_equity
B13: Inventories (start of year) | C13: ='Balance Sheet'!D7 -> 25120 | D13: BAL_inventories_2023 | E13: startYear_inventory
B14: Receivables (start of year) | C14: ='Balance Sheet'!D6 -> 38015 | D14: BAL_receivables_2023 | E14: startYear_receivables
B15: Total assets (start of year) | C15: ='Balance Sheet'!D20 -> 376317 | D15: BAL_assets_total_2023 | E15: startYear_total_assets
B16: Total capitalization (start of year) | C16: ='Balance Sheet'!H10+'Balance Sheet'!H19 -> 250021 | D16: BAL_debt_long_term_2023 + BAL_equity_shareholders_2023 | E16: startYear_total_capitalization
B18: ─── Current Year (Derived) ───
B19: After-tax operating income | C19: ='Income Statement'!C8+(1-C8)*'Income Statement'!C11 -> 67480.53 | D19: INC_ebit + (1−tax_rate) × INC_interest_expense | E19: currentYear_after_tax_operating_income
B20: Average daily sales | C20: ='Income Statement'!C4/365 -> 929.44384 | D20: INC_sales / 365 | E20: currentYear_daily_sales_average
B21: Book value of equity | C21: ='Balance Sheet'!G19 -> 277087 | D21: BAL_equity_shareholders_2024 | E21: currentYear_equity
B22: Cash | C22: ='Balance Sheet'!C5 -> 23029 | D22: BAL_cash_2024 | E22: currentYear_cash
B23: Current assets | C23: ='Balance Sheet'!C9 -> 90990 | D23: BAL_assets_current_2024 | E23: currentYear_assets_current
B24: Current liabilities | C24: ='Balance Sheet'!G8 -> 72330 | D24: BAL_liabilities_current_2024 | E24: currentYear_liabilities_current
B25: Daily COGS | C25: ='Income Statement'!C5/365 -> 654.96712 | D25: INC_cost_goods_sold / 365 | E25: currentYear_cost_goods_sold_daily
B26: Long-term debt | C26: ='Balance Sheet'!G10 -> 35365 | D26: BAL_debt_long_term_2024 | E26: currentYear_debt_long_term
B27: Net working capital | C27: ='Balance Sheet'!C9-'Balance Sheet'!G8 -> 18660 | D27: BAL_assets_current_2024 − BAL_liabilities_current_2024 | E27: currentYear_working_capital_net
B28: Total assets | C28: ='Balance Sheet'!C20 -> 453475 | D28: BAL_assets_total_2024 | E28: currentYear_assets_total
B29: Total capitalization | C29: ='Balance Sheet'!G10+'Balance Sheet'!G19 -> 312452 | D29: BAL_debt_long_term_2024 + BAL_equity_shareholders_2024 | E29: currentYear_total_capitalization
B30: Total liabilities | C30: ='Balance Sheet'!G13 -> 183502 | D30: BAL_liabilities_total_2024 | E30: currentYear_liabilities_total
B32: ─── Mixed Year (Averages) ───
B33: Average equity | C33: =AVERAGE(C12,C21) -> 244812.5 | D33: AVERAGE(startYear_equity, currentYear_equity) | E33: avg_equity
B34: Average total assets | C34: =AVERAGE(C15,C28) -> 414896 | D34: AVERAGE(startYear_total_assets, currentYear_assets_total) | E34: avg_total_assets
B35: Average total capitalization | C35: =AVERAGE(C16,C29) -> 281236.5 | D35: AVERAGE(startYear_total_capitalization, currentYear_total_capitalization) | E35: avg_total_capitalization
B36: Long-term debt + Equity | C36: =C26+C21 -> 312452 | D36: currentYear_debt_long_term + currentYear_equity | E36: debt_long_term_equity
B39: Ratio | C39: Output ← Completed | D39: Named Range Formula (reference) | E39: Named Range
B40: Performance
B41: Market value added (MVA) | C41: =C9-C21 -> 168873.48 | D41: market_capitalization − currentYear_equity
B42: Market-to-book ratio | C42: =C9/C21 -> 1.6094601 | D42: market_capitalization / currentYear_equity
B43: Economic value added (EVA) | C43: =C19-(C7*C16) -> 44978.64 | D43: currentYear_after_tax_operating_income − (cost_capital × startYear_total_capitalization)
B45: Profitability
B46: Return on assets (ROA) | C46: =C19/C15 -> 0.17931832 | D46: currentYear_after_tax_operating_income / startYear_total_assets
...

Sheet Notes
B1: Notes & Assumptions — Exxon Mobil Corporation (XOM)
B3: Company: | C3: Exxon Mobil Corporation
B4: Ticker: | C4: XOM
B5: Industry: | C5: Energy – Integrated Oil & Gas
B6: Fiscal Year (current): | C6: FY2024 (Dec 31, 2024)
B7: Fiscal Year (prior): | C7: FY2023 (Dec 31, 2023)
B8: Data Source: | C8: ExxonMobil 10-K FY2024, SEC EDGAR; Q4 2024 Earnings Press Release
B9: Units: | C9: All figures in millions of US dollars unless otherwise noted.
B10: Tax Rate: | C10: 28.3% — effective tax rate from 10-K (income taxes / pretax income)
B11: Cost of Capital: | C11: 9.0% — estimated WACC; students may refine using CAPM + class methodology
B12: Share Price: | C12: $103.76 — closing price on December 31, 2024
B13: Shares Outstanding: | C13: 4,298M shares (diluted, FY2024 average)
B15: BUS-314 Project Use: | C15: This workbook provides real financial statement data for the Accounting & Performance Ratios project.
... B25: Cash Flow Notes: | C25: CFO per press release = $55,022M. Some working capital line items are estimated from balance sheet changes.
